Workbook

Sheet Сегодня
A1: Сегодня | B1: Зулькайнаров Умарбек
A2: Оценки | B2: ='Неделя'!G2 -> 17 мар. вт
A3: =data!A70 -> Русский язык | B3: ='Неделя'!G3
A4: =data!A71 -> Литература | B4: ='Неделя'!G4
A5: =data!A72 -> Узбекский язык | B5: ='Неделя'!G5
A6: =data!A73 -> Английский язык | B6: ='Неделя'!G6
A7: =data!A74 -> История | B7: ='Неделя'!G7
A8: =data!A75 -> Воспитание | B8: ='Неделя'!G8
A9: =data!A76 -> Физкультура | B9: ='Неделя'!G9
A10: =data!A77 -> Математика | B10: ='Неделя'!G10 -> 4
A11: =data!A78 -> Ботаника | B11: ='Неделя'!G11
A12: =data!A79 -> География | B12: ='Неделя'!G12
A13: =data!A80 -> ИЗО | B13: ='Неделя'!G13
A14: =data!A81 -> Технология | B14: ='Неделя'!G14
... A21: =data!A88 | B21: ='Неделя'!G21

Sheet Неделя
A1: Оценки за неделю | B1: Столбец 2 | C1: Столбец 3 | D1: Столбец 4 | E1: Столбец 5 | F1: Столбец 6 | G1: Столбец 7
A2: Дата | B2: =CONCATENATE(TEXT(TODAY()-5,"d mmm")," ",TEXT(WEEKDAY(TODAY()-5),"Ddd")) -> 12 мар. чт | C2: =CONCATENATE(TEXT(TODAY()-4,"d mmm")," ",TEXT(WEEKDAY(TODAY()-4),"DDD")) -> 13 мар. пт | D2: =CONCATENATE(TEXT(TODAY()-3,"d mmm")," ",TEXT(WEEKDAY(TODAY()-3),"DDD")) -> 14 мар. сб | E2: =CONCATENATE(TEXT(TODAY()-2,"d mmm")," ",TEXT(WEEKDAY(TODAY()-2),"DDD")) -> 15 мар. вс | F2: =CONCATENATE(TEXT(TODAY()-1,"d mmm")," ",TEXT(WEEKDAY(TODAY()-1),"DDD")) -> 16 мар. пн | G2: =CONCATENATE(TEXT(TODAY(),"d mmm")," ",TEXT(WEEKDAY(TODAY()),"DDD")) -> 17 мар. вт
A3: =data!A70 -> Русский язык | B3: =IFERROR(__xludf.DUMMYFUNCTION("FILTER(data!$B$70:$JE$89,data!$B$69:$JE$69=B32)"),"") | C3: =IFERROR(__xludf.DUMMYFUNCTION("FILTER(data!$B$70:$JE$89,data!$B$69:$JE$69=C32)")," ") | D3: =IFERROR(__xludf.DUMMYFUNCTION("FILTER(data!$B$70:$JE$89,data!$B$69:$JE$69=D32)")," ") | E3: =IFERROR(__xludf.DUMMYFUNCTION("FILTER(data!$B$70:$JE$89,data!$B$69:$JE$69=E32)")," ") | F3: =IFERROR(__xludf.DUMMYFUNCTION("FILTER(data!$B$70:$JE$89,data!$B$69:$JE$69=F32)")," ") | G3: =IFERROR(__xludf.DUMMYFUNCTION("FILTER(data!$B$70:$JE$89,data!$B$69:$JE$69=G32)"),"")
A4: =data!A71 -> Литература | B4: =IFERROR(__xludf.DUMMYFUNCTION("""COMPUTED_VALUE"""),"4") -> 4 | C4: =IFERROR(__xludf.DUMMYFUNCTION("""COMPUTED_VALUE""")," ") | D4: =IFERROR(__xludf.DUMMYFUNCTION("""COMPUTED_VALUE""")," ") | E4: =IFERROR(__xludf.DUMMYFUNCTION("""COMPUTED_VALUE""")," ") | F4: =IFERROR(__xludf.DUMMYFUNCTION("""COMPUTED_VALUE""")," ") | G4: =IFERROR(__xludf.DUMMYFUNCTION("""COMPUTED_VALUE""")," ")
A5: =data!A72 -> Узбекский язык | B5: =IFERROR(__xludf.DUMMYFUNCTION("""COMPUTED_VALUE"""),"3") -> 3 | C5: =IFERROR(__xludf.DUMMYFUNCTION("""COMPUTED_VALUE"""),"") | D5: =IFERROR(__xludf.DUMMYFUNCTION("""COMPUTED_VALUE"""),"") | E5: =IFERROR(__xludf.DUMMYFUNCTION("""COMPUTED_VALUE""")," ") | F5: =IFERROR(__xludf.DUMMYFUNCTION("""COMPUTED_VALUE""")," ") | G5: =IFERROR(__xludf.DUMMYFUNCTION("""COMPUTED_VALUE""")," ")
A6: =data!A73 -> Английский язык | B6: =IFERROR(__xludf.DUMMYFUNCTION("""COMPUTED_VALUE"""),"дз") -> дз | C6: =IFERROR(__xludf.DUMMYFUNCTION("""COMPUTED_VALUE"""),"") | D6: =IFERROR(__xludf.DUMMYFUNCTION("""COMPUTED_VALUE""")," ") | E6: =IFERROR(__xludf.DUMMYFUNCTION("""COMPUTED_VALUE""")," ") | F6: =IFERROR(__xludf.DUMMYFUNCTION("""COMPUTED_VALUE""")," ") | G6: =IFERROR(__xludf.DUMMYFUNCTION("""COMPUTED_VALUE""")," ")
A7: =data!A74 -> История | B7: =IFERROR(__xludf.DUMMYFUNCTION("""COMPUTED_VALUE""")," ") | C7: =IFERROR(__xludf.DUMMYFUNCTION("""COMPUTED_VALUE""")," ") | D7: =IFERROR(__xludf.DUMMYFUNCTION("""COMPUTED_VALUE""")," ") | E7: =IFERROR(__xludf.DUMMYFUNCTION("""COMPUTED_VALUE""")," ") | F7: =IFERROR(__xludf.DUMMYFUNCTION("""COMPUTED_VALUE"""),"4") -> 4 | G7: =IFERROR(__xludf.DUMMYFUNCTION("""COMPUTED_VALUE"""),"")
A8: =data!A75 -> Воспитание | B8: =IFERROR(__xludf.DUMMYFUNCTION("""COMPUTED_VALUE""")," ") | C8: =IFERROR(__xludf.DUMMYFUNCTION("""COMPUTED_VALUE""")," ") | D8: =IFERROR(__xludf.DUMMYFUNCTION("""COMPUTED_VALUE""")," ") | E8: =IFERROR(__xludf.DUMMYFUNCTION("""COMPUTED_VALUE""")," ") | F8: =IFERROR(__xludf.DUMMYFUNCTION("""COMPUTED_VALUE"""),"5") -> 5 | G8: =IFERROR(__xludf.DUMMYFUNCTION("""COMPUTED_VALUE""")," ")
A9: =data!A76 -> Физкультура | B9: =IFERROR(__xludf.DUMMYFUNCTION("""COMPUTED_VALUE""")," ") | C9: =IFERROR(__xludf.DUMMYFUNCTION("""COMPUTED_VALUE""")," ") | D9: =IFERROR(__xludf.DUMMYFUNCTION("""COMPUTED_VALUE""")," ") | E9: =IFERROR(__xludf.DUMMYFUNCTION("""COMPUTED_VALUE""")," ") | F9: =IFERROR(__xludf.DUMMYFUNCTION("""COMPUTED_VALUE"""),"") | G9: =IFERROR(__xludf.DUMMYFUNCTION("""COMPUTED_VALUE""")," ")
A10: =data!A77 -> Математика | B10: =IFERROR(__xludf.DUMMYFUNCTION("""COMPUTED_VALUE"""),"") | C10: =IFERROR(__xludf.DUMMYFUNCTION("""COMPUTED_VALUE""")," ") | D10: =IFERROR(__xludf.DUMMYFUNCTION("""COMPUTED_VALUE"""),"5") -> 5 | E10: =IFERROR(__xludf.DUMMYFUNCTION("""COMPUTED_VALUE""")," ") | F10: =IFERROR(__xludf.DUMMYFUNCTION("""COMPUTED_VALUE""")," ") | G10: =IFERROR(__xludf.DUMMYFUNCTION("""COMPUTED_VALUE"""),"4") -> 4
A11: =data!A78 -> Ботаника | B11: =IFERROR(__xludf.DUMMYFUNCTION("""COMPUTED_VALUE"""),"") | C11: =IFERROR(__xludf.DUMMYFUNCTION("""COMPUTED_VALUE""")," ") | D11: =IFERROR(__xludf.DUMMYFUNCTION("""COMPUTED_VALUE""")," ") | E11: =IFERROR(__xludf.DUMMYFUNCTION("""COMPUTED_VALUE""")," ") | F11: =IFERROR(__xludf.DUMMYFUNCTION("""COMPUTED_VALUE""")," ") | G11: =IFERROR(__xludf.DUMMYFUNCTION("""COMPUTED_VALUE""")," ")
A12: =data!A79 -> География | B12: =IFERROR(__xludf.DUMMYFUNCTION("""COMPUTED_VALUE""")," ") | C12: =IFERROR(__xludf.DUMMYFUNCTION("""COMPUTED_VALUE""")," ") | D12: =IFERROR(__xludf.DUMMYFUNCTION("""COMPUTED_VALUE"""),"н") -> н | E12: =IFERROR(__xludf.DUMMYFUNCTION("""COMPUTED_VALUE""")," ") | F12: =IFERROR(__xludf.DUMMYFUNCTION("""COMPUTED_VALUE""")," ") | G12: =IFERROR(__xludf.DUMMYFUNCTION("""COMPUTED_VALUE""")," ")
A13: =data!A80 -> ИЗО | B13: =IFERROR(__xludf.DUMMYFUNCTION("""COMPUTED_VALUE""")," ") | C13: =IFERROR(__xludf.DUMMYFUNCTION("""COMPUTED_VALUE""")," ") | D13: =IFERROR(__xludf.DUMMYFUNCTION("""COMPUTED_VALUE""")," ") | E13: =IFERROR(__xludf.DUMMYFUNCTION("""COMPUTED_VALUE""")," ") | F13: =IFERROR(__xludf.DUMMYFUNCTION("""COMPUTED_VALUE"""),"") | G13: =IFERROR(__xludf.DUMMYFUNCTION("""COMPUTED_VALUE""")," ")
A14: =data!A81 -> Технология | B14: =IFERROR(__xludf.DUMMYFUNCTION("""COMPUTED_VALUE""")," ") | C14: =IFERROR(__xludf.DUMMYFUNCTION("""COMPUTED_VALUE""")," ") | D14: =IFERROR(__xludf.DUMMYFUNCTION("""COMPUTED_VALUE""")," ") | E14: =IFERROR(__xludf.DUMMYFUNCTION("""COMPUTED_VALUE""")," ") | F14: =IFERROR(__xludf.DUMMYFUNCTION("""COMPUTED_VALUE""")," ") | G14: =IFERROR(__xludf.DUMMYFUNCTION("""COMPUTED_VALUE""")," ")
A15: =data!A82 -> Информатика | B15: =IFERROR(__xludf.DUMMYFUNCTION("""COMPUTED_VALUE""")," ") | C15: =IFERROR(__xludf.DUMMYFUNCTION("""COMPUTED_VALUE""")," ") | D15: =IFERROR(__xludf.DUMMYFUNCTION("""COMPUTED_VALUE"""),"") | E15: =IFERROR(__xludf.DUMMYFUNCTION("""COMPUTED_VALUE""")," ") | F15: =IFERROR(__xludf.DUMMYFUNCTION("""COMPUTED_VALUE""")," ") | G15: =IFERROR(__xludf.DUMMYFUNCTION("""COMPUTED_VALUE""")," ")
A16: =data!A83 -> Музыка | B16: =IFERROR(__xludf.DUMMYFUNCTION("""COMPUTED_VALUE""")," ") | C16: =IFERROR(__xludf.DUMMYFUNCTION("""COMPUTED_VALUE""")," ") | D16: =IFERROR(__xludf.DUMMYFUNCTION("""COMPUTED_VALUE""")," ") | E16: =IFERROR(__xludf.DUMMYFUNCTION("""COMPUTED_VALUE""")," ") | F16: =IFERROR(__xludf.DUMMYFUNCTION("""COMPUTED_VALUE"""),"") | G16: =IFERROR(__xludf.DUMMYFUNCTION("""COMPUTED_VALUE""")," ")
A17: =data!A84 -> Физика | B17: =IFERROR(__xludf.DUMMYFUNCTION("""COMPUTED_VALUE""")," ") | C17: =IFERROR(__xludf.DUMMYFUNCTION("""COMPUTED_VALUE"""),"5") -> 5 | D17: =IFERROR(__xludf.DUMMYFUNCTION("""COMPUTED_VALUE""")," ") | E17: =IFERROR(__xludf.DUMMYFUNCTION("""COMPUTED_VALUE""")," ") | F17: =IFERROR(__xludf.DUMMYFUNCTION("""COMPUTED_VALUE""")," ") | G17: =IFERROR(__xludf.DUMMYFUNCTION("""COMPUTED_VALUE""")," ")
A18: =data!A85 -> Посещаемость | B18: =IFERROR(__xludf.DUMMYFUNCTION("""COMPUTED_VALUE""")," ") | C18: =IFERROR(__xludf.DUMMYFUNCTION("""COMPUTED_VALUE""")," ") | D18: =IFERROR(__xludf.DUMMYFUNCTION("""COMPUTED_VALUE""")," ") | E18: =IFERROR(__xludf.DUMMYFUNCTION("""COMPUTED_VALUE""")," ") | F18: =IFERROR(__xludf.DUMMYFUNCTION("""COMPUTED_VALUE""")," ") | G18: =IFERROR(__xludf.DUMMYFUNCTION("""COMPUTED_VALUE""")," ")
A19: =data!A86 | B19: =IFERROR(__xludf.DUMMYFUNCTION("""COMPUTED_VALUE""")," ") | C19: =IFERROR(__xludf.DUMMYFUNCTION("""COMPUTED_VALUE""")," ") | D19: =IFERROR(__xludf.DUMMYFUNCTION("""COMPUTED_VALUE""")," ") | E19: =IFERROR(__xludf.DUMMYFUNCTION("""COMPUTED_VALUE""")," ") | F19: =IFERROR(__xludf.DUMMYFUNCTION("""COMPUTED_VALUE""")," ") | G19: =IFERROR(__xludf.DUMMYFUNCTION("""COMPUTED_VALUE""")," ")
A20: =data!A87 | B20: =IFERROR(__xludf.DUMMYFUNCTION("""COMPUTED_VALUE""")," ") | C20: =IFERROR(__xludf.DUMMYFUNCTION("""COMPUTED_VALUE""")," ") | D20: =IFERROR(__xludf.DUMMYFUNCTION("""COMPUTED_VALUE""")," ") | E20: =IFERROR(__xludf.DUMMYFUNCTION("""COMPUTED_VALUE""")," ") | F20: =IFERROR(__xludf.DUMMYFUNCTION("""COMPUTED_VALUE""")," ") | G20: =IFERROR(__xludf.DUMMYFUNCTION("""COMPUTED_VALUE""")," ")
A21: =data!A88 | B21: =IFERROR(__xludf.DUMMYFUNCTION("""COMPUTED_VALUE""")," ") | C21: =IFERROR(__xludf.DUMMYFUNCTION("""COMPUTED_VALUE""")," ") | D21: =IFERROR(__xludf.DUMMYFUNCTION("""COMPUTED_VALUE""")," ") | E21: =IFERROR(__xludf.DUMMYFUNCTION("""COMPUTED_VALUE""")," ") | F21: =IFERROR(__xludf.DUMMYFUNCTION("""COMPUTED_VALUE""")," ") | G21: =IFERROR(__xludf.DUMMYFUNCTION("""COMPUTED_VALUE""")," ")
B22: =IFERROR(__xludf.DUMMYFUNCTION("""COMPUTED_VALUE""")," ") | C22: =IFERROR(__xludf.DUMMYFUNCTION("""COMPUTED_VALUE""")," ") | D22: =IFERROR(__xludf.DUMMYFUNCTION("""COMPUTED_VALUE""")," ") | E22: =IFERROR(__xludf.DUMMYFUNCTION("""COMPUTED_VALUE""")," ") | F22: =IFERROR(__xludf.DUMMYFUNCTION("""COMPUTED_VALUE""")," ") | G22: =IFERROR(__xludf.DUMMYFUNCTION("""COMPUTED_VALUE""")," ")
B32: =TEXT(TODAY()-5,"d mmmm") -> 12 марта | C32: =TEXT(TODAY()-4,"d mmmm") -> 13 марта | D32: =TEXT(TODAY()-3,"d mmmm") -> 14 марта | E32: =TEXT(TODAY()-2,"d mmmm") -> 15 марта | F32: =TEXT(TODAY()-1,"d mmmm") -> 16 марта | G32: =TEXT(TODAY(),"d mmmm") -> 17 марта

Sheet Все оценки
A1: Оценки все даты | B1: Столбец 2 | C1: Столбец 3 | D1: Столбец 4 | E1: Столбец 5 | F1: Столбец 6 | G1: Столбец 7 | H1: Столбец 8 | I1: Столбец 9 | J1: Столбец 10 | K1: Столбец 11 | L1: Столбец 12 | M1: Столбец 13 | N1: Столбец 14 | O1: Столбец 15 | P1: Столбец 16 | Q1: Столбец 17 | R1: Столбец 18 | S1: Столбец 19 | T1: Столбец 20 | U1: Столбец 21 | V1: Столбец 22 | W1: Столбец 23 | X1: Столбец 24 | Y1: Столбец 25 | Z1: Столбец 26 | AA1: Столбец 27 | AB1: Столбец 28 | AC1: Столбец 29 | AD1: Столбец 30 | AE1: Столбец 31 | AF1: Столбец 32 | AG1: Столбец 33 | AH1: Столбец 34 | AI1: Столбец 35 | AJ1: Столбец 36 | AK1: Столбец 37 | AL1: Столбец 38 | AM1: Столбец 39 | AN1: Столбец 40 | AO1: Столбец 41 | AP1: Столбец 42 | AQ1: Столбец 43 | AR1: Столбец 44 | AS1: Столбец 45 | AT1: Столбец 46 | AU1: Столбец 47 | AV1: Столбец 48 | AW1: Столбец 49 | AX1: Столбец 50 | AY1: Столбец 51 | AZ1: Столбец 52 | BA1: Столбец 53 | BB1: Столбец 54 | BC1: Столбец 55 | BD1: Столбец 56 | BE1: Столбец 57 | BF1: Столбец 58 | BG1: Столбец 59 | BH1: Столбец 60 | BI1: Столбец 61 | BJ1: Столбец 62 | BK1: Столбец 63 | BL1: Столбец 64 | BM1: Столбец 65 | BN1: Столбец 66 | BO1: Столбец 67 | BP1: Столбец 68 | BQ1: Столбец 69 | BR1: Столбец 70 | BS1: Столбец 71 | BT1: Столбец 72 | BU1: Столбец 73 | BV1: Столбец 74 | BW1: Столбец 75 | BX1: Столбец 76 | BY1: Столбец 77 | BZ1: Столбец 78 | CA1: Столбец 79 | CB1: Столбец 80 | CC1: Столбец 81 | CD1: Столбец 82 | CE1: Столбец 83 | CF1: Столбец 84 | CG1: Столбец 85 | CH1: Столбец 86 | CI1: Столбец 87 | CJ1: Столбец 88 | CK1: Столбец 89 | CL1: Столбец 90 | CM1: Столбец 91 | CN1: Столбец 92 | CO1: Столбец 93 | CP1: Столбец 94 | CQ1: Столбец 95 | CR1: Столбец 96 | CS1: Столбец 97 | CT1: Столбец 98 | CU1: Столбец 99 | CV1: Столбец 100 | CW1: Столбец 101 | CX1: Столбец 102 | CY1: Столбец 103 | CZ1: Столбец 104 | DA1: Столбец 105 | DB1: Столбец 106 | DC1: Столбец 107 | DD1: Столбец 108 | DE1: Столбец 109 | DF1: Столбец 110 | DG1: Столбец 111 | DH1: Столбец 112 | DI1: Столбец 113 | DJ1: Столбец 114 | DK1: Столбец 115 | DL1: Столбец 116 | DM1: Столбец 117 | DN1: Столбец 118 | DO1: Столбец 119 | DP1: Столбец 120 | DQ1: Столбец 121 | DR1: Столбец 122 | DS1: Столбец 123 | DT1: Столбец 124 | DU1: Столбец 125 | DV1: Столбец 126 | DW1: Столбец 127 | DX1: Столбец 128 | DY1: Столбец 129 | DZ1: Столбец 130 | EA1: Столбец 131 | EB1: Столбец 132 | EC1: Столбец 133 | ED1: Столбец 134 | EE1: Столбец 135 | EF1: Столбец 136 | EG1: Столбец 137 | EH1: Столбец 138 | EI1: Столбец 139 | EJ1: Столбец 140 | EK1: Столбец 141 | EL1: Столбец 142 | EM1: Столбец 143 | EN1: Столбец 144 | EO1: Столбец 145 | EP1: Столбец 146 | EQ1: Столбец 147 | ER1: Столбец 148 | ES1: Столбец 149 | ET1: Столбец 150 | EU1: Столбец 151 | EV1: Столбец 152 | EW1: Столбец 153 | EX1: Столбец 154 | EY1: Столбец 155 | EZ1: Столбец 156 | FA1: Столбец 157 | FB1: Столбец 158 | FC1: Столбец 159 | FD1: Столбец 160 | FE1: Столбец 161 | FF1: Столбец 162 | FG1: Столбец 163 | FH1: Столбец 164 | FI1: Столбец 165 | FJ1: Столбец 166 | FK1: Столбец 167 | FL1: Столбец 168 | FM1: Столбец 169 | FN1: Столбец 170 | FO1: Столбец 171 | FP1: Столбец 172 | FQ1: Столбец 173 | FR1: Столбец 174 | FS1: Столбец 175 | FT1: Столбец 176 | FU1: Столбец 177 | FV1: Столбец 178 | FW1: Столбец 179 | FX1: Столбец 180 | FY1: Столбец 181 | FZ1: Столбец 182 | GA1: Столбец 183 | GB1: Столбец 184 | GC1: Столбец 185 | GD1: Столбец 186 | GE1: Столбец 187 | GF1: Столбец 188 | GG1: Столбец 189 | GH1: Столбец 190 | GI1: Столбец 191 | GJ1: Столбец 192 | GK1: Столбец 193 | GL1: Столбец 194 | GM1: Столбец 195 | GN1: Столбец 196 | GO1: Столбец 197 | GP1: Столбец 198 | GQ1: Столбец 199 | GR1: Столбец 200 | GS1: Столбец 201 | GT1: Столбец 202 | GU1: Столбец 203 | GV1: Столбец 204 | GW1: Столбец 205 | GX1: Столбец 206 | GY1: Столбец 207 | GZ1: Столбец 208 | HA1: Столбец 209 | HB1: Столбец 210 | HC1: Столбец 211 | HD1: Столбец 212 | HE1: Столбец 213 | HF1: Столбец 214 | HG1: Столбец 215 | HH1: Столбец 216 | HI1: Столбец 217 | HJ1: Столбец 218 | HK1: Столбец 219 | HL1: Столбец 220 | HM1: Столбец 221 | HN1: Столбец 222 | HO1: Столбец 223 | HP1: Столбец 224 | HQ1: Столбец 225 | HR1: Столбец 226 | HS1: Столбец 227 | HT1: Столбец 228 | HU1: Столбец 229 | HV1: Столбец 230 | HW1: Столбец 231 | HX1: Столбец 232 | HY1: Столбец 233 | HZ1: Столбец 234 | IA1: Столбец 235 | IB1: Столбец 236 | IC1: Столбец 237 | ID1: Столбец 238 | IE1: Столбец 239 | IF1: Столбец 240 | IG1: Столбец 241 | IH1: Столбец 242 | II1: Столбец 243 | IJ1: Столбец 244 | IK1: Столбец 245 | IL1: Столбец 246 | IM1: Столбец 247 | IN1: Столбец 248 | IO1: Столбец 249 | IP1: Столбец 250 | IQ1: Столбец 251 | IR1: Столбец 252 | IS1: Столбец 253 | IT1: Столбец 254 | IU1: Столбец 255 | IV1: Столбец 256 | IW1: Столбец 257 | IX1: Столбец 258 | IY1: Столбец 259 | IZ1: Столбец 260 | JA1: Столбец 261 | JB1: Столбец 262 | JC1: Столбец 263 | JD1: Столбец 264 | JE1: Столбец 265
A2: =data!A69 -> Оценки | B2: =data!B69 -> 2 сентября | C2: =data!C69 -> 3 сентября | D2: =data!D69 -> 4 сентября | E2: =data!E69 -> 5 сентября | F2: =data!F69 -> 6 сентября | G2: =data!G69 -> 7 сентября | H2: =data!H69 -> 8 сентября | ... JE2: =data!JE69 -> 23 мая
A3: =data!A70 -> Русский язык | B3: =data!B70 | C3: =data!C70 | D3: =data!D70 -> 5 | E3: =data!E70 | F3: =data!F70 | G3: =data!G70 | H3: =data!H70 | ... JE3: =data!JE70
A4: =data!A71 -> Литература | B4: =data!B71 | C4: =data!C71 | D4: =data!D71 -> 5 | E4: =data!E71 | F4: =data!F71 | G4: =data!G71 | H4: =data!H71 | ... JE4: =data!JE71
A5: =data!A72 -> Узбекский язык | B5: =data!B72 | C5: =data!C72 | D5: =data!D72 | E5: =data!E72 | F5: =data!F72 | G5: =data!G72 | H5: =data!H72 | ... JE5: =data!JE72
A6: =data!A73 -> Английский язык | B6: =data!B73 | C6: =data!C73 -> 5 | D6: =data!D73 | E6: =data!E73 -> 2 | F6: =data!F73 | G6: =data!G73 | H6: =data!H73 | ... JE6: =data!JE73
A7: =data!A74 -> История | B7: =data!B74 | C7: =data!C74 | D7: =data!D74 | E7: =data!E74 | F7: =data!F74 | G7: =data!G74 | H7: =data!H74 | ... JE7: =data!JE74
A8: =data!A75 -> Воспитание | B8: =data!B75 | C8: =data!C75 | D8: =data!D75 | E8: =data!E75 | F8: =data!F75 | G8: =data!G75 | H8: =data!H75 | ... JE8: =data!JE75
A9: =data!A76 -> Физкультура | B9: =data!B76 | C9: =data!C76 | D9: =data!D76 | E9: =data!E76 | F9: =data!F76 -> 5 | G9: =data!G76 | H9: =data!H76 -> 5 | ... JE9: =data!JE76
A10: =data!A77 -> Математика | B10: =data!B77 | C10: =data!C77 | D10: =data!D77 | E10: =data!E77 | F10: =data!F77 | G10: =data!G77 | H10: =data!H77 | ... JE10: =data!JE77
A11: =data!A78 -> Ботаника | B11: =data!B78 | C11: =data!C78 -> 4 | D11: =data!D78 | E11: =data!E78 | F11: =data!F78 | G11: =data!G78 | H11: =data!H78 | ... JE11: =data!JE78
A12: =data!A79 -> География | B12: =data!B79 | C12: =data!C79 | D12: =data!D79 | E12: =data!E79 | F12: =data!F79 | G12: =data!G79 | H12: =data!H79 -> 4 | ... JE12: =data!JE79
A13: =data!A80 -> ИЗО | B13: =data!B80 | C13: =data!C80 | D13: =data!D80 | E13: =data!E80 | F13: =data!F80 | G13: =data!G80 | H13: =data!H80 | ... JE13: =data!JE80
... A21: =data!A88 | B21: =data!B88 | C21: =data!C88 | D21: =data!D88 | E21: =data!E88 | F21: =data!F88 | G21: =data!G88 | H21: =data!H88 | ... JE21: =data!JE88

Sheet Четверти
A1: Предварительно четверть | B1: 1 Четверть | C1: 2 Четверть | D1: 3 Четверть | E1: 4 Четверть | F1: Год
A2: =data!A70 -> Русский язык | B2: =IFERROR(HLOOKUP(B$1,data!$B$2:$JE$3,2,0),"") -> 4 | C2: =IFERROR(IF(ISNUMBER(HLOOKUP("1 полугодие",data!$B$2:$JE$3,2,0)),HLOOKUP("1 полугодие",data!$B$2:$JE$3,2,0),HLOOKUP(C$1,data!$B$2:$JE$3,2,0)),"") -> 4 | D2: =IFERROR(HLOOKUP(D$1,data!$B$2:$JE$3,2,0),"") -> 4 | E2: =IFERROR(IF(ISNUMBER(HLOOKUP("2 полугодие",data!$B$2:$JE$3,2,0)),HLOOKUP("2 полугодие",data!$B$2:$JE$3,2,0),HLOOKUP(E$1,data!$B$2:$JE$3,2,0)),"") | F2: =IFERROR(HLOOKUP(F$1,data!$B$2:$JE$3,2,0),"")
A3: =data!A71 -> Литература | B3: =IFERROR(HLOOKUP(B$1,data!$B$5:$JE$6,2,0),"") -> 5 | C3: =IFERROR(IF(ISNUMBER(HLOOKUP("1 полугодие",data!$B$5:$JE$6,2,0)),HLOOKUP("1 полугодие",data!$B$5:$JE$6,2,0),HLOOKUP(C$1,data!$B$5:$JE$6,2,0)),"") -> 4 | D3: =IFERROR(HLOOKUP(D$1,data!$B$5:$JE$6,2,0),"") -> 4 | E3: =IFERROR(IF(ISNUMBER(HLOOKUP("2 полугодие",data!$B$5:$JE$6,2,0)),HLOOKUP("2 полугодие",data!$B$5:$JE$6,2,0),HLOOKUP(E$1,data!$B$5:$JE$6,2,0)),"") | F3: =IFERROR(HLOOKUP(F$1,data!$B$5:$JE$6,2,0),"")
A4: =data!A72 -> Узбекский язык | B4: =IFERROR(HLOOKUP(B$1,data!$B$8:$JE$9,2,0),"") -> 3 | C4: =IFERROR(IF(ISNUMBER(HLOOKUP("1 полугодие",data!$B$8:$JE$9,2,0)),HLOOKUP("1 полугодие",data!$B$8:$JE$9,2,0),HLOOKUP(C$1,data!$B$8:$JE$9,2,0)),"") -> 4 | D4: =IFERROR(HLOOKUP(D$1,data!$B$8:$JE$9,2,0),"") -> 3 | E4: =IFERROR(IF(ISNUMBER(HLOOKUP("2 полугодие",data!$B$8:$JE$9,2,0)),HLOOKUP("2 полугодие",data!$B$8:$JE$9,2,0),HLOOKUP(E$1,data!$B$8:$JE$9,2,0)),"") | F4: =IFERROR(HLOOKUP(F$1,data!$B$8:$JE$9,2,0),"")
A5: =data!A73 -> Английский язык | B5: =IFERROR(HLOOKUP(B$1,data!$B$11:$JE$12,2,0),"") -> 4 | C5: =IFERROR(IF(ISNUMBER(HLOOKUP("1 полугодие",data!$B$11:$JE$12,2,0)),HLOOKUP("1 полугодие",data!$B$11:$JE$12,2,0),HLOOKUP(C$1,data!$B$11:$JE$12,2,0)),"") -> 4 | D5: =IFERROR(HLOOKUP(D$1,data!$B$11:$JE$12,2,0),"") -> 4 | E5: =IFERROR(IF(ISNUMBER(HLOOKUP("2 полугодие",data!$B$11:$JE$12,2,0)),HLOOKUP("2 полугодие",data!$B$11:$JE$12,2,0),HLOOKUP(E$1,data!$B$11:$JE$12,2,0)),"") | F5: =IFERROR(HLOOKUP(F$1,data!$B$11:$JE$12,2,0),"")
A6: =data!A74 -> История | B6: =IFERROR(HLOOKUP(B$1,data!$B$14:$JE$15,2,0),"") -> 4 | C6: =IFERROR(IF(ISNUMBER(HLOOKUP("1 полугодие",data!$B$14:$JE$15,2,0)),HLOOKUP("1 полугодие",data!$B$14:$JE$15,2,0),HLOOKUP(C$1,data!$B$14:$JE$15,2,0)),"") -> 5 | D6: =IFERROR(HLOOKUP(D$1,data!$B$14:$JE$15,2,0),"") -> 4 | E6: =IFERROR(IF(ISNUMBER(HLOOKUP("2 полугодие",data!$B$14:$JE$15,2,0)),HLOOKUP("2 полугодие",data!$B$14:$JE$15,2,0),HLOOKUP(E$1,data!$B$14:$JE$15,2,0)),"") | F6: =IFERROR(HLOOKUP(F$1,data!$B$14:$JE$15,2,0),"")
A7: =data!A75 -> Воспитание | B7: =IFERROR(HLOOKUP(B$1,data!$B$17:$JE$18,2,0),"") | C7: =IFERROR(IF(ISNUMBER(HLOOKUP("1 полугодие",data!$B$17:$JE$18,2,0)),HLOOKUP("1 полугодие",data!$B$17:$JE$18,2,0),HLOOKUP(C$1,data!$B$17:$JE$18,2,0)),"") -> 5 | D7: =IFERROR(HLOOKUP(D$1,data!$B$17:$JE$18,2,0),"") | E7: =IFERROR(IF(ISNUMBER(HLOOKUP("2 полугодие",data!$B$17:$JE$18,2,0)),HLOOKUP("2 полугодие",data!$B$17:$JE$18,2,0),HLOOKUP(E$1,data!$B$17:$JE$18,2,0)),"") -> 4 | F7: =IFERROR(HLOOKUP(F$1,data!$B$17:$JE$18,2,0),"")
A8: =data!A76 -> Физкультура | B8: =IFERROR(HLOOKUP(B$1,data!$B$20:$JE$21,2,0),"") -> 4 | C8: =IFERROR(IF(ISNUMBER(HLOOKUP("1 полугодие",data!$B$20:$JE$21,2,0)),HLOOKUP("1 полугодие",data!$B$20:$JE$21,2,0),HLOOKUP(C$1,data!$B$20:$JE$21,2,0)),"") -> 4 | D8: =IFERROR(HLOOKUP(D$1,data!$B$20:$JE$21,2,0),"") -> 5 | E8: =IFERROR(IF(ISNUMBER(HLOOKUP("2 полугодие",data!$B$20:$JE$21,2,0)),HLOOKUP("2 полугодие",data!$B$20:$JE$21,2,0),HLOOKUP(E$1,data!$B$20:$JE$21,2,0)),"") | F8: =IFERROR(HLOOKUP(F$1,data!$B$20:$JE$21,2,0),"")
A9: =data!A77 -> Математика | B9: =IFERROR(HLOOKUP(B$1,data!$B$23:$JE$24,2,0),"") -> 5 | C9: =IFERROR(IF(ISNUMBER(HLOOKUP("1 полугодие",data!$B$23:$JE$24,2,0)),HLOOKUP("1 полугодие",data!$B$23:$JE$24,2,0),HLOOKUP(C$1,data!$B$23:$JE$24,2,0)),"") -> 4 | D9: =IFERROR(HLOOKUP(D$1,data!$B$23:$JE$24,2,0),"") -> 4 | E9: =IFERROR(IF(ISNUMBER(HLOOKUP("2 полугодие",data!$B$23:$JE$24,2,0)),HLOOKUP("2 полугодие",data!$B$23:$JE$24,2,0),HLOOKUP(E$1,data!$B$23:$JE$24,2,0)),"") | F9: =IFERROR(HLOOKUP(F$1,data!$B$23:$JE$24,2,0),"")
A10: =data!A78 -> Ботаника | B10: =IFERROR(HLOOKUP(B$1,data!$B$26:$JE$27,2,0),"") | C10: =IFERROR(IF(ISNUMBER(HLOOKUP("1 полугодие",data!$B$26:$JE$27,2,0)),HLOOKUP("1 полугодие",data!$B$26:$JE$27,2,0),HLOOKUP(C$1,data!$B$26:$JE$27,2,0)),"") -> 5 | D10: =IFERROR(HLOOKUP(D$1,data!$B$26:$JE$27,2,0),"") | E10: =IFERROR(IF(ISNUMBER(HLOOKUP("2 полугодие",data!$B$26:$JE$27,2,0)),HLOOKUP("2 полугодие",data!$B$26:$JE$27,2,0),HLOOKUP(E$1,data!$B$26:$JE$27,2,0)),"") -> 4 | F10: =IFERROR(HLOOKUP(F$1,data!$B$26:$JE$27,2,0),"")
A11: =data!A79 -> География | B11: =IFERROR(HLOOKUP(B$1,data!$B$29:$JE$30,2,0),"") | C11: =IFERROR(IF(ISNUMBER(HLOOKUP("1 полугодие",data!$B$29:$JE$30,2,0)),HLOOKUP("1 полугодие",data!$B$29:$JE$30,2,0),HLOOKUP(C$1,data!$B$29:$JE$30,2,0)),"") -> 5 | D11: =IFERROR(HLOOKUP(D$1,data!$B$29:$JE$30,2,0),"") | E11: =IFERROR(IF(ISNUMBER(HLOOKUP("2 полугодие",data!$B$29:$JE$30,2,0)),HLOOKUP("2 полугодие",data!$B$29:$JE$30,2,0),HLOOKUP(E$1,data!$B$29:$JE$30,2,0)),"") | F11: =IFERROR(HLOOKUP(F$1,data!$B$29:$JE$30,2,0),"")
A12: =data!A80 -> ИЗО | B12: =IFERROR(HLOOKUP(B$1,data!$B$32:$JE$33,2,0),"") | C12: =IFERROR(IF(ISNUMBER(HLOOKUP("1 полугодие",data!$B$32:$JE$33,2,0)),HLOOKUP("1 полугодие",data!$B$32:$JE$33,2,0),HLOOKUP(C$1,data!$B$32:$JE$33,2,0)),"") -> 5 | D12: =IFERROR(HLOOKUP(D$1,data!$B$32:$JE$33,2,0),"") | E12: =IFERROR(IF(ISNUMBER(HLOOKUP("2 полугодие",data!$B$32:$JE$33,2,0)),HLOOKUP("2 полугодие",data!$B$32:$JE$33,2,0),HLOOKUP(E$1,data!$B$32:$JE$33,2,0)),"") | F12: =IFERROR(HLOOKUP(F$1,data!$B$32:$JE$33,2,0),"")
A13: =data!A81 -> Технология | B13: =IFERROR(HLOOKUP(B$1,data!$B$35:$JE$36,2,0),"") | C13: =IFERROR(IF(ISNUMBER(HLOOKUP("1 полугодие",data!$B$35:$JE$36,2,0)),HLOOKUP("1 полугодие",data!$B$35:$JE$36,2,0),HLOOKUP(C$1,data!$B$35:$JE$36,2,0)),"") -> 5 | D13: =IFERROR(HLOOKUP(D$1,data!$B$35:$JE$36,2,0),"") | E13: =IFERROR(IF(ISNUMBER(HLOOKUP("2 полугодие",data!$B$35:$JE$36,2,0)),HLOOKUP("2 полугодие",data!$B$35:$JE$36,2,0),HLOOKUP(E$1,data!$B$35:$JE$36,2,0)),"") | F13: =IFERROR(HLOOKUP(F$1,data!$B$35:$JE$36,2,0),"")
A14: =data!A82 -> Информатика | B14: =IFERROR(HLOOKUP(B$1,data!$B$38:$JE$39,2,0),"") | C14: =IFERROR(IF(ISNUMBER(HLOOKUP("1 полугодие",data!$B$38:$JE$39,2,0)),HLOOKUP("1 полугодие",data!$B$38:$JE$39,2,0),HLOOKUP(C$1,data!$B$38:$JE$39,2,0)),"") -> 5 | D14: =IFERROR(HLOOKUP(D$1,data!$B$38:$JE$39,2,0),"") | E14: =IFERROR(IF(ISNUMBER(HLOOKUP("2 полугодие",data!$B$38:$JE$39,2,0)),HLOOKUP("2 полугодие",data!$B$38:$JE$39,2,0),HLOOKUP(E$1,data!$B$38:$JE$39,2,0)),"") -> 4 | F14: =IFERROR(HLOOKUP(F$1,data!$B$38:$JE$39,2,0),"") -> 4.5
A15: =data!A83 -> Музыка | B15: =IFERROR(HLOOKUP(B$1,data!$B$41:$JE$42,2,0),"") | C15: =IFERROR(IF(ISNUMBER(HLOOKUP("1 полугодие",data!$B$41:$JE$42,2,0)),HLOOKUP("1 полугодие",data!$B$41:$JE$42,2,0),HLOOKUP(C$1,data!$B$41:$JE$42,2,0)),"") -> 5 | D15: =IFERROR(HLOOKUP(D$1,data!$B$41:$JE$42,2,0),"") | E15: =IFERROR(IF(ISNUMBER(HLOOKUP("2 полугодие",data!$B$41:$JE$42,2,0)),HLOOKUP("2 полугодие",data!$B$41:$JE$42,2,0),HLOOKUP(E$1,data!$B$41:$JE$42,2,0)),"") -> 5 | F15: =IFERROR(HLOOKUP(F$1,data!$B$41:$JE$42,2,0),"")
A16: =data!A84 -> Физика | B16: =IFERROR(HLOOKUP(B$1,data!$B$44:$JE$45,2,0),"") -> 4 | C16: =IFERROR(IF(ISNUMBER(HLOOKUP("1 полугодие",data!$B$44:$JE$45,2,0)),HLOOKUP("1 полугодие",data!$B$44:$JE$45,2,0),HLOOKUP(C$1,data!$B$44:$JE$45,2,0)),"") -> 4 | D16: =IFERROR(HLOOKUP(D$1,data!$B$44:$JE$45,2,0),"") -> 5 | E16: =IFERROR(IF(ISNUMBER(HLOOKUP("2 полугодие",data!$B$44:$JE$45,2,0)),HLOOKUP("2 полугодие",data!$B$44:$JE$45,2,0),HLOOKUP(E$1,data!$B$44:$JE$45,2,0)),"") | F16: =IFERROR(HLOOKUP(F$1,data!$B$44:$JE$45,2,0),"")
A17: =data!A85 -> Посещаемость | B17: =IFERROR(HLOOKUP(B$1,data!$B$47:$JE$48,2,0),"") | C17: =IFERROR(IF(ISNUMBER(HLOOKUP("1 полугодие",data!$B$47:$JE$48,2,0)),HLOOKUP("1 полугодие",data!$B$47:$JE$48,2,0),HLOOKUP(C$1,data!$B$47:$JE$48,2,0)),"") | D17: =IFERROR(HLOOKUP(D$1,data!$B$47:$JE$48,2,0),"") | E17: =IFERROR(IF(ISNUMBER(HLOOKUP("2 полугодие",data!$B$47:$JE$48,2,0)),HLOOKUP("2 полугодие",data!$B$47:$JE$48,2,0),HLOOKUP(E$1,data!$B$47:$JE$48,2,0)),"") | F17: =IFERROR(HLOOKUP(F$1,data!$B$47:$JE$48,2,0)," ")
A18: =data!A86 | B18: =IFERROR(HLOOKUP(B$1,data!$B$50:$JE$51,2,0),"") | C18: =IFERROR(IF(ISNUMBER(HLOOKUP("1 полугодие",data!$B$50:$JE$51,2,0)),HLOOKUP("1 полугодие",data!$B$50:$JE$51,2,0),HLOOKUP(C$1,data!$B$50:$JE$51,2,0)),"") | D18: =IFERROR(HLOOKUP(D$1,data!$B$50:$JE$51,2,0),"") | E18: =IFERROR(IF(ISNUMBER(HLOOKUP("2 полугодие",data!$B$50:$JE$51,2,0)),HLOOKUP("2 полугодие",data!$B$50:$JE$51,2,0),HLOOKUP(E$1,data!$B$50:$JE$51,2,0)),"") | F18: =IFERROR(HLOOKUP(F$1,data!$B$50:$JE$51,2,0)," ")
A19: =data!A87 | B19: =IFERROR(HLOOKUP(B$1,data!$B$53:$JE$54,2,0),"") | C19: =IFERROR(IF(ISNUMBER(HLOOKUP("1 полугодие",data!$B$53:$JE$54,2,0)),HLOOKUP("1 полугодие",data!$B$53:$JE$54,2,0),HLOOKUP(C$1,data!$B$53:$JE$54,2,0)),"") | D19: =IFERROR(HLOOKUP(D$1,data!$B$53:$JE$54,2,0),"") | E19: =IFERROR(IF(ISNUMBER(HLOOKUP("2 полугодие",data!$B$53:$JE$54,2,0)),HLOOKUP("2 полугодие",data!$B$53:$JE$54,2,0),HLOOKUP(E$1,data!$B$53:$JE$54,2,0)),"") | F19: =IFERROR(HLOOKUP(F$1,data!$B$53:$JE$54,2,0)," ")
A20: =data!A88 | B20: =IFERROR(HLOOKUP(B$1,data!$B$56:$JE$57,2,0),"") | C20: =IFERROR(IF(ISNUMBER(HLOOKUP("1 полугодие",data!$B$56:$JE$57,2,0)),HLOOKUP("1 полугодие",data!$B$56:$JE$57,2,0),HLOOKUP(C$1,data!$B$56:$JE$57,2,0)),"") | D20: =IFERROR(HLOOKUP(D$1,data!$B$56:$JE$57,2,0),"") | E20: =IFERROR(IF(ISNUMBER(HLOOKUP("2 полугодие",data!$B$56:$JE$57,2,0)),HLOOKUP("2 полугодие",data!$B$56:$JE$57,2,0),HLOOKUP(E$1,data!$B$56:$JE$57,2,0)),"") | F20: =IFERROR(HLOOKUP(F$1,data!$B$56:$JE$57,2,0),"")

Sheet data
A1: ='Сегодня'!B1 -> Зулькайнаров Умарбек | B1: 2 | C1: 3 | D1: 4 | E1: 5 | F1: 6 | G1: 7 | H1: 8 | I1: 9 | J1: 10 | K1: 11 | L1: 12 | M1: 13 | N1: 14 | O1: 15 | P1: 16 | Q1: 17 | R1: 18 | S1: 19 | T1: 20 | U1: 21 | V1: 22 | W1: 23 | X1: 24 | Y1: 25 | Z1: 26 | AA1: 27 | AB1: 28 | AC1: 29 | AD1: 30 | AE1: 31 | AF1: 32 | AG1: 33 | AH1: 34 | AI1: 35 | AJ1: 36 | AK1: 37 | AL1: 38 | AM1: 39 | AN1: 40 | AO1: 41 | AP1: 42 | AQ1: 43 | AR1: 44 | AS1: 45 | AT1: 46 | AU1: 47 | AV1: 48 | AW1: 49 | AX1: 50 | AY1: 51 | AZ1: 52 | BA1: 53 | BB1: 54 | BC1: 55 | BD1: 56 | BE1: 57 | BF1: 58 | BG1: 59 | BH1: 60 | BI1: 61 | BJ1: 62 | BK1: 63 | BL1: 64 | BM1: 65 | BN1: 66 | BO1: 67 | BP1: 68 | BQ1: 69 | BR1: 70 | BS1: 71 | BT1: 72 | BU1: 73 | BV1: 74 | BW1: 75 | BX1: 76 | BY1: 77 | BZ1: 78 | CA1: 79 | CB1: 80 | CC1: 81 | CD1: 82 | CE1: 83 | CF1: 84 | CG1: 85 | CH1: 86 | CI1: 87 | CJ1: 88 | CK1: 89 | CL1: 90 | CM1: 91 | CN1: 92 | CO1: 93 | CP1: 94 | CQ1: 95 | CR1: 96 | CS1: 97 | CT1: 98 | CU1: 99 | CV1: 100 | CW1: 101 | CX1: 102 | CY1: 103 | CZ1: 104 | DA1: 105 | DB1: 106 | DC1: 107 | DD1: 108 | DE1: 109 | DF1: 110 | DG1: 111 | DH1: 112 | DI1: 113 | DJ1: 114 | DK1: 115 | DL1: 116 | DM1: 117 | DN1: 118 | DO1: 119 | DP1: 120 | DQ1: 121 | DR1: 122 | DS1: 123 | DT1: 124 | DU1: 125 | DV1: 126 | DW1: 127 | DX1: 128 | DY1: 129 | DZ1: 130 | EA1: 131 | EB1: 132 | EC1: 133 | ED1: 134 | EE1: 135 | EF1: 136 | EG1: 137 | EH1: 138 | EI1: 139 | EJ1: 140 | EK1: 141 | EL1: 142 | EM1: 143 | EN1: 144 | EO1: 145 | EP1: 146 | EQ1: 147 | ER1: 148 | ES1: 149 | ET1: 150 | EU1: 151 | EV1: 152 | EW1: 153 | EX1: 154 | EY1: 155 | EZ1: 156 | FA1: 157 | FB1: 158 | FC1: 159 | FD1: 160 | FE1: 161 | FF1: 162 | FG1: 163 | FH1: 164 | FI1: 165 | FJ1: 166 | FK1: 167 | FL1: 168 | FM1: 169 | FN1: 170 | FO1: 171 | FP1: 172 | FQ1: 173 | FR1: 174 | FS1: 175 | FT1: 176 | FU1: 177 | FV1: 178 | FW1: 179 | FX1: 180 | FY1: 181 | FZ1: 182 | GA1: 183 | GB1: 184 | GC1: 185 | GD1: 186 | GE1: 187 | GF1: 188 | GG1: 189 | GH1: 190 | GI1: 191 | GJ1: 192 | GK1: 193 | GL1: 194 | GM1: 195 | GN1: 196 | GO1: 197 | GP1: 198 | GQ1: 199 | GR1: 200 | GS1: 201 | GT1: 202 | GU1: 203 | GV1: 204 | GW1: 205 | GX1: 206 | GY1: 207 | GZ1: 208 | HA1: 209 | HB1: 210 | HC1: 211 | HD1: 212 | HE1: 213 | HF1: 214 | HG1: 215 | HH1: 216 | HI1: 217 | HJ1: 218 | HK1: 219 | HL1: 220 | HM1: 221 | HN1: 222 | HO1: 223 | HP1: 224 | HQ1: 225 | HR1: 226 | HS1: 227 | HT1: 228 | HU1: 229 | HV1: 230 | HW1: 231 | HX1: 232 | HY1: 233 | HZ1: 234 | IA1: 235 | IB1: 236 | IC1: 237 | ID1: 238 | IE1: 239 | IF1: 240 | IG1: 241 | IH1: 242 | II1: 243 | IJ1: 244 | IK1: 245 | IL1: 246 | IM1: 247 | IN1: 248 | IO1: 249 | IP1: 250 | IQ1: 251 | IR1: 252 | IS1: 253 | IT1: 254 | IU1: 255 | IV1: 256 | IW1: 257 | IX1: 258 | IY1: 259 | IZ1: 260 | JA1: 261
A2: Журнал 6 Nova 2025-2026 | B2: =IFERROR(__xludf.DUMMYFUNCTION("IMPORTRANGE($A$2, CONCATENATE($A3,""!C4:JB4""))"),45902.0) -> 45902 | C2: =IFERROR(__xludf.DUMMYFUNCTION("""COMPUTED_VALUE"""),45904.0) -> 45904 | D2: =IFERROR(__xludf.DUMMYFUNCTION("""COMPUTED_VALUE"""),45909.0) -> 45909 | E2: =IFERROR(__xludf.DUMMYFUNCTION("""COMPUTED_VALUE"""),45911.0) -> 45911 | I2: =IFERROR(__xludf.DUMMYFUNCTION("""COMPUTED_VALUE"""),45551.0) -> 45551 | J2: =IFERROR(__xludf.DUMMYFUNCTION("""COMPUTED_VALUE"""),45923.0) -> 45923 | K2: =IFERROR(__xludf.DUMMYFUNCTION("""COMPUTED_VALUE"""),45960.0) -> 45960 | L2: =IFERROR(__xludf.DUMMYFUNCTION("""COMPUTED_VALUE"""),"02.20.2025") -> 02.20.2025 | P2: =IFERROR(__xludf.DUMMYFUNCTION("""COMPUTED_VALUE"""),45937.0) -> 45937 | Q2: =IFERROR(__xludf.DUMMYFUNCTION("""COMPUTED_VALUE"""),45939.0) -> 45939 | R2: =IFERROR(__xludf.DUMMYFUNCTION("""COMPUTED_VALUE"""),45975.0) -> 45975 | S2: =IFERROR(__xludf.DUMMYFUNCTION("""COMPUTED_VALUE"""),45951.0) -> 45951 | W2: =IFERROR(__xludf.DUMMYFUNCTION("""COMPUTED_VALUE"""),45953.0) -> 45953 | X2: =IFERROR(__xludf.DUMMYFUNCTION("""COMPUTED_VALUE"""),45958.0) -> 45958 | BM2: =IFERROR(__xludf.DUMMYFUNCTION("""COMPUTED_VALUE"""),"1 четверть") -> 1 четверть | BN2: =IFERROR(__xludf.DUMMYFUNCTION("""COMPUTED_VALUE"""),45972.0) -> 45972 | BO2: =IFERROR(__xludf.DUMMYFUNCTION("""COMPUTED_VALUE"""),45979.0) -> 45979 | BP2: =IFERROR(__xludf.DUMMYFUNCTION("""COMPUTED_VALUE"""),45981.0) -> 45981 | BQ2: =IFERROR(__xludf.DUMMYFUNCTION("""COMPUTED_VALUE"""),45986.0) -> 45986 | BU2: =IFERROR(__xludf.DUMMYFUNCTION("""COMPUTED_VALUE"""),45993.0) -> 45993 | BV2: =IFERROR(__xludf.DUMMYFUNCTION("""COMPUTED_VALUE"""),45995.0) -> 45995 | BW2: =IFERROR(__xludf.DUMMYFUNCTION("""COMPUTED_VALUE"""),46000.0) -> 46000 | BX2: =IFERROR(__xludf.DUMMYFUNCTION("""COMPUTED_VALUE"""),46007.0) -> 46007 | CB2: =IFERROR(__xludf.DUMMYFUNCTION("""COMPUTED_VALUE"""),46009.0) -> 46009 | CC2: =IFERROR(__xludf.DUMMYFUNCTION("""COMPUTED_VALUE"""),46014.0) -> 46014 | DR2: =IFERROR(__xludf.DUMMYFUNCTION("""COMPUTED_VALUE"""),"2 четверть") -> 2 четверть | DS2: =IFERROR(__xludf.DUMMYFUNCTION("""COMPUTED_VALUE"""),46035.0) -> 46035 | DT2: =IFERROR(__xludf.DUMMYFUNCTION("""COMPUTED_VALUE"""),46037.0) -> 46037 | DU2: =IFERROR(__xludf.DUMMYFUNCTION("""COMPUTED_VALUE"""),46044.0) -> 46044 | DV2: =IFERROR(__xludf.DUMMYFUNCTION("""COMPUTED_VALUE"""),46049.0) -> 46049 | DZ2: =IFERROR(__xludf.DUMMYFUNCTION("""COMPUTED_VALUE"""),"в/д") -> в/д | EA2: =IFERROR(__xludf.DUMMYFUNCTION("""COMPUTED_VALUE"""),46056.0) -> 46056 | EB2: =IFERROR(__xludf.DUMMYFUNCTION("""COMPUTED_VALUE"""),46058.0) -> 46058 | EC2: =IFERROR(__xludf.DUMMYFUNCTION("""COMPUTED_VALUE"""),46063.0) -> 46063 | EG2: =IFERROR(__xludf.DUMMYFUNCTION("""COMPUTED_VALUE"""),46065.0) -> 46065 | EH2: =IFERROR(__xludf.DUMMYFUNCTION("""COMPUTED_VALUE"""),46070.0) -> 46070 | EI2: =IFERROR(__xludf.DUMMYFUNCTION("""COMPUTED_VALUE"""),46077.0) -> 46077 | EJ2: =IFERROR(__xludf.DUMMYFUNCTION("""COMPUTED_VALUE"""),46079.0) -> 46079 | EN2: =IFERROR(__xludf.DUMMYFUNCTION("""COMPUTED_VALUE"""),46084.0) -> 46084 | EO2: =IFERROR(__xludf.DUMMYFUNCTION("""COMPUTED_VALUE"""),46086.0) -> 46086 | EP2: =IFERROR(__xludf.DUMMYFUNCTION("""COMPUTED_VALUE"""),46091.0) -> 46091 | EQ2: =IFERROR(__xludf.DUMMYFUNCTION("""COMPUTED_VALUE"""),46093.0) -> 46093 | EU2: =IFERROR(__xludf.DUMMYFUNCTION("""COMPUTED_VALUE"""),46098.0) -> 46098 | EV2: =IFERROR(__xludf.DUMMYFUNCTION("""COMPUTED_VALUE"""),46100.0) -> 46100 | GK2: =IFERROR(__xludf.DUMMYFUNCTION("""COMPUTED_VALUE"""),"3 четверть") -> 3 четверть | IS2: =IFERROR(__xludf.DUMMYFUNCTION("""COMPUTED_VALUE"""),"4 четверть") -> 4 четверть | IT2: =IFERROR(__xludf.DUMMYFUNCTION("""COMPUTED_VALUE"""),"год") -> год | IU2: =IFERROR(__xludf.DUMMYFUNCTION("""COMPUTED_VALUE"""),"рейтинг") -> рейтинг | IX2: =IFERROR(__xludf.DUMMYFUNCTION("""COMPUTED_VALUE"""),"Дата") -> Дата | IY2: =IFERROR(__xludf.DUMMYFUNCTION("""COMPUTED_VALUE"""),"Тема урока") -> Тема урока | IZ2: =IFERROR(__xludf.DUMMYFUNCTION("""COMPUTED_VALUE"""),"Домашнее задание") -> Домашнее задание | JA2: =IFERROR(__xludf.DUMMYFUNCTION("""COMPUTED_VALUE"""),"Дата") -> Дата
